2019-10-30 11:36:08,702:__main__:ERROR - HTTPConnectionPool(host='localhost', port=20167): Max retries exceeded with url: /api/pbx (Caused by NewConnectionError('<urllib3.connection.HTTPConnection object at 0x000002685E400048>: Failed to establish a new connection: [WinError 10061] No connection could be made because the target machine actively refused it',))
Traceback (most recent call last):
  File "C:\Program Files\Python36\lib\site-packages\urllib3\connection.py", line 141, in _new_conn
    (self.host, self.port), self.timeout, **extra_kw)
  File "C:\Program Files\Python36\lib\site-packages\urllib3\util\connection.py", line 83, in create_connection
    raise err
  File "C:\Program Files\Python36\lib\site-packages\urllib3\util\connection.py", line 73, in create_connection
    sock.connect(sa)
ConnectionRefusedError: [WinError 10061] No connection could be made because the target machine actively refused it

During handling of the above exception, another exception occurred:

Traceback (most recent call last):
  File "C:\Program Files\Python36\lib\site-packages\urllib3\connectionpool.py", line 601, in urlopen
    chunked=chunked)
  File "C:\Program Files\Python36\lib\site-packages\urllib3\connectionpool.py", line 357, in _make_request
    conn.request(method, url, **httplib_request_kw)
  File "C:\Program Files\Python36\lib\http\client.py", line 1239, in request
    self._send_request(method, url, body, headers, encode_chunked)
  File "C:\Program Files\Python36\lib\http\client.py", line 1285, in _send_request
    self.endheaders(body, encode_chunked=encode_chunked)
  File "C:\Program Files\Python36\lib\http\client.py", line 1234, in endheaders
    self._send_output(message_body, encode_chunked=encode_chunked)
  File "C:\Program Files\Python36\lib\http\client.py", line 1026, in _send_output
    self.send(msg)
  File "C:\Program Files\Python36\lib\http\client.py", line 964, in send
    self.connect()
  File "C:\Program Files\Python36\lib\site-packages\urllib3\connection.py", line 166, in connect
    conn = self._new_conn()
  File "C:\Program Files\Python36\lib\site-packages\urllib3\connection.py", line 150, in _new_conn
    self, "Failed to establish a new connection: %s" % e)
urllib3.exceptions.NewConnectionError: <urllib3.connection.HTTPConnection object at 0x000002685E400048>: Failed to establish a new connection: [WinError 10061] No connection could be made because the target machine actively refused it

During handling of the above exception, another exception occurred:

Traceback (most recent call last):
  File "C:\Program Files\Python36\lib\site-packages\requests\adapters.py", line 440, in send
    timeout=timeout
  File "C:\Program Files\Python36\lib\site-packages\urllib3\connectionpool.py", line 639, in urlopen
    _stacktrace=sys.exc_info()[2])
  File "C:\Program Files\Python36\lib\site-packages\urllib3\util\retry.py", line 388, in increment
    raise MaxRetryError(_pool, url, error or ResponseError(cause))
urllib3.exceptions.MaxRetryError: HTTPConnectionPool(host='localhost', port=20167): Max retries exceeded with url: /api/pbx (Caused by NewConnectionError('<urllib3.connection.HTTPConnection object at 0x000002685E400048>: Failed to establish a new connection: [WinError 10061] No connection could be made because the target machine actively refused it',))

During handling of the above exception, another exception occurred:

Traceback (most recent call last):
  File "C:\Users\ainur.fadzil\Documents\metasubs_py\createpbx.py", line 188, in createpbx
    k = requests.post(u, json=data, verify=False)
  File "C:\Program Files\Python36\lib\site-packages\requests\api.py", line 112, in post
    return request('post', url, data=data, json=json, **kwargs)
  File "C:\Program Files\Python36\lib\site-packages\requests\api.py", line 58, in request
    return session.request(method=method, url=url, **kwargs)
  File "C:\Program Files\Python36\lib\site-packages\requests\sessions.py", line 508, in request
    resp = self.send(prep, **send_kwargs)
  File "C:\Program Files\Python36\lib\site-packages\requests\sessions.py", line 618, in send
    r = adapter.send(request, **kwargs)
  File "C:\Program Files\Python36\lib\site-packages\requests\adapters.py", line 508, in send
    raise ConnectionError(e, request=request)
requests.exceptions.ConnectionError: HTTPConnectionPool(host='localhost', port=20167): Max retries exceeded with url: /api/pbx (Caused by NewConnectionError('<urllib3.connection.HTTPConnection object at 0x000002685E400048>: Failed to establish a new connection: [WinError 10061] No connection could be made because the target machine actively refused it',))
2019-10-30 11:36:13,002:__main__:ERROR - HTTPConnectionPool(host='localhost', port=20167): Max retries exceeded with url: /api/pbx (Caused by NewConnectionError('<urllib3.connection.HTTPConnection object at 0x000002685E3C8588>: Failed to establish a new connection: [WinError 10061] No connection could be made because the target machine actively refused it',))
Traceback (most recent call last):
  File "C:\Program Files\Python36\lib\site-packages\urllib3\connection.py", line 141, in _new_conn
    (self.host, self.port), self.timeout, **extra_kw)
  File "C:\Program Files\Python36\lib\site-packages\urllib3\util\connection.py", line 83, in create_connection
    raise err
  File "C:\Program Files\Python36\lib\site-packages\urllib3\util\connection.py", line 73, in create_connection
    sock.connect(sa)
ConnectionRefusedError: [WinError 10061] No connection could be made because the target machine actively refused it

During handling of the above exception, another exception occurred:

Traceback (most recent call last):
  File "C:\Program Files\Python36\lib\site-packages\urllib3\connectionpool.py", line 601, in urlopen
    chunked=chunked)
  File "C:\Program Files\Python36\lib\site-packages\urllib3\connectionpool.py", line 357, in _make_request
    conn.request(method, url, **httplib_request_kw)
  File "C:\Program Files\Python36\lib\http\client.py", line 1239, in request
    self._send_request(method, url, body, headers, encode_chunked)
  File "C:\Program Files\Python36\lib\http\client.py", line 1285, in _send_request
    self.endheaders(body, encode_chunked=encode_chunked)
  File "C:\Program Files\Python36\lib\http\client.py", line 1234, in endheaders
    self._send_output(message_body, encode_chunked=encode_chunked)
  File "C:\Program Files\Python36\lib\http\client.py", line 1026, in _send_output
    self.send(msg)
  File "C:\Program Files\Python36\lib\http\client.py", line 964, in send
    self.connect()
  File "C:\Program Files\Python36\lib\site-packages\urllib3\connection.py", line 166, in connect
    conn = self._new_conn()
  File "C:\Program Files\Python36\lib\site-packages\urllib3\connection.py", line 150, in _new_conn
    self, "Failed to establish a new connection: %s" % e)
urllib3.exceptions.NewConnectionError: <urllib3.connection.HTTPConnection object at 0x000002685E3C8588>: Failed to establish a new connection: [WinError 10061] No connection could be made because the target machine actively refused it

During handling of the above exception, another exception occurred:

Traceback (most recent call last):
  File "C:\Program Files\Python36\lib\site-packages\requests\adapters.py", line 440, in send
    timeout=timeout
  File "C:\Program Files\Python36\lib\site-packages\urllib3\connectionpool.py", line 639, in urlopen
    _stacktrace=sys.exc_info()[2])
  File "C:\Program Files\Python36\lib\site-packages\urllib3\util\retry.py", line 388, in increment
    raise MaxRetryError(_pool, url, error or ResponseError(cause))
urllib3.exceptions.MaxRetryError: HTTPConnectionPool(host='localhost', port=20167): Max retries exceeded with url: /api/pbx (Caused by NewConnectionError('<urllib3.connection.HTTPConnection object at 0x000002685E3C8588>: Failed to establish a new connection: [WinError 10061] No connection could be made because the target machine actively refused it',))

During handling of the above exception, another exception occurred:

Traceback (most recent call last):
  File "C:\Users\ainur.fadzil\Documents\metasubs_py\createpbx.py", line 188, in createpbx
    k = requests.post(u, json=data, verify=False)
  File "C:\Program Files\Python36\lib\site-packages\requests\api.py", line 112, in post
    return request('post', url, data=data, json=json, **kwargs)
  File "C:\Program Files\Python36\lib\site-packages\requests\api.py", line 58, in request
    return session.request(method=method, url=url, **kwargs)
  File "C:\Program Files\Python36\lib\site-packages\requests\sessions.py", line 508, in request
    resp = self.send(prep, **send_kwargs)
  File "C:\Program Files\Python36\lib\site-packages\requests\sessions.py", line 618, in send
    r = adapter.send(request, **kwargs)
  File "C:\Program Files\Python36\lib\site-packages\requests\adapters.py", line 508, in send
    raise ConnectionError(e, request=request)
requests.exceptions.ConnectionError: HTTPConnectionPool(host='localhost', port=20167): Max retries exceeded with url: /api/pbx (Caused by NewConnectionError('<urllib3.connection.HTTPConnection object at 0x000002685E3C8588>: Failed to establish a new connection: [WinError 10061] No connection could be made because the target machine actively refused it',))
