2019-09-11 02:48:23,739:__main__:ERROR - HTTPSConnectionPool(host='billing.redtone.com', port=443): Max retries exceeded with url: /metaswitchapi2/api/subs/01548738066 (Caused by NewConnectionError('<urllib3.connection.VerifiedHTTPSConnection object at 0x000000891CBA4B70>: Failed to establish a new connection: [Errno 11001] getaddrinfo failed',))
Traceback (most recent call last):
  File "E:\Python36\lib\site-packages\urllib3\connection.py", line 141, in _new_conn
    (self.host, self.port), self.timeout, **extra_kw)
  File "E:\Python36\lib\site-packages\urllib3\util\connection.py", line 60, in create_connection
    for res in socket.getaddrinfo(host, port, family, socket.SOCK_STREAM):
  File "E:\Python36\lib\socket.py", line 745, in getaddrinfo
    for res in _socket.getaddrinfo(host, port, family, type, proto, flags):
socket.gaierror: [Errno 11001] getaddrinfo failed

During handling of the above exception, another exception occurred:

Traceback (most recent call last):
  File "E:\Python36\lib\site-packages\urllib3\connectionpool.py", line 601, in urlopen
    chunked=chunked)
  File "E:\Python36\lib\site-packages\urllib3\connectionpool.py", line 346, in _make_request
    self._validate_conn(conn)
  File "E:\Python36\lib\site-packages\urllib3\connectionpool.py", line 850, in _validate_conn
    conn.connect()
  File "E:\Python36\lib\site-packages\urllib3\connection.py", line 284, in connect
    conn = self._new_conn()
  File "E:\Python36\lib\site-packages\urllib3\connection.py", line 150, in _new_conn
    self, "Failed to establish a new connection: %s" % e)
urllib3.exceptions.NewConnectionError: <urllib3.connection.VerifiedHTTPSConnection object at 0x000000891CBA4B70>: Failed to establish a new connection: [Errno 11001] getaddrinfo failed

During handling of the above exception, another exception occurred:

Traceback (most recent call last):
  File "E:\Python36\lib\site-packages\requests\adapters.py", line 440, in send
    timeout=timeout
  File "E:\Python36\lib\site-packages\urllib3\connectionpool.py", line 639, in urlopen
    _stacktrace=sys.exc_info()[2])
  File "E:\Python36\lib\site-packages\urllib3\util\retry.py", line 388, in increment
    raise MaxRetryError(_pool, url, error or ResponseError(cause))
urllib3.exceptions.MaxRetryError: HTTPSConnectionPool(host='billing.redtone.com', port=443): Max retries exceeded with url: /metaswitchapi2/api/subs/01548738066 (Caused by NewConnectionError('<urllib3.connection.VerifiedHTTPSConnection object at 0x000000891CBA4B70>: Failed to establish a new connection: [Errno 11001] getaddrinfo failed',))

During handling of the above exception, another exception occurred:

Traceback (most recent call last):
  File "deletesubscriber.py", line 17, in deletesubs
    k = requests.delete(u, verify=False)
  File "E:\Python36\lib\site-packages\requests\api.py", line 152, in delete
    return request('delete', url, **kwargs)
  File "E:\Python36\lib\site-packages\requests\api.py", line 58, in request
    return session.request(method=method, url=url, **kwargs)
  File "E:\Python36\lib\site-packages\requests\sessions.py", line 508, in request
    resp = self.send(prep, **send_kwargs)
  File "E:\Python36\lib\site-packages\requests\sessions.py", line 618, in send
    r = adapter.send(request, **kwargs)
  File "E:\Python36\lib\site-packages\requests\adapters.py", line 508, in send
    raise ConnectionError(e, request=request)
requests.exceptions.ConnectionError: HTTPSConnectionPool(host='billing.redtone.com', port=443): Max retries exceeded with url: /metaswitchapi2/api/subs/01548738066 (Caused by NewConnectionError('<urllib3.connection.VerifiedHTTPSConnection object at 0x000000891CBA4B70>: Failed to establish a new connection: [Errno 11001] getaddrinfo failed',))
